Workbook

Sheet Face Report

Sheet SOFP
A1: PT DUMMY - C DAN ENTITAS ANAK | N1: PT DUMMY - C AND SUBSIDIARIES
A2: LAPORAN POSISI KEUANGAN KONSOLIDASI | N2: CONSOLIDATED STATEMENTS OF FINANCIAL POSITION
A3: 31 DESEMBER 2024, 2023 DAN 2022 | N3: DECEMBER 31, 2024, 2023 AND 2022
A4: (Disajikan dalam Rupiah, kecuali dinyatakan lain) | N4: (Expressed in Rupiah, unless otherwise stated)
G7: Catatan/ | J7: 31 Desember 2024/ | L7: 31 Desember 2023/ | N7: 31 Desember 2022/
G8: Notes | J8: December 31, 2024 | L8: December 31, 2023 | N8: December 31, 2022
A10: ASET | P10: ASSETS
A11: ASET LANCAR | P11: CURRENT ASSETS
A12: Kas dan bank | J12: ='Consol SoFP 24'!AH15 -> 61178535792 | L12: ='Consol SoFP 23 & 22'!AE15 -> 75109486095 | N12: ='Consol SoFP 23 & 22'!BF15 -> 40661258337 | P12: Cash and banks
A13: Piutang usaha | J13: =SUM('Consol SoFP 24'!AH17:AH18,'Consol SoFP 24'!AH20) -> 244672056004 | L13: =SUM('Consol SoFP 23 & 22'!AE17:AE18,'Consol SoFP 23 & 22'!AE20) -> 323260364520 | N13: =SUM('Consol SoFP 23 & 22'!BF17:BF18) -> 227940501708 | P13: Trade receivables
A14: Piutang sewa | J14: ='Consol SoFP 24'!AH22 -> 5217740512 | L14: ='Consol SoFP 23 & 22'!AE22 -> 15830303102 | N14: ='Consol SoFP 23 & 22'!BF22 -> 14442442151 | P14: Lease Receivables
A15: Piutang lain-lain | J15: =SUM('Consol SoFP 24'!AH23,'Consol SoFP 24'!AH28:AH29,'Consol SoFP 24'!AH25) -> 62971200011 | L15: =SUM('Consol SoFP 23 & 22'!AE28:AE29) -> 38356602143 | N15: ='Consol SoFP 23 & 22'!BF28 -> 5434584686 | P15: Other receivables
A16: Piutang pihak berelasi | J16: =SUM('Consol SoFP 24'!AH26) -> 131678101647 | L16: ='Consol SoFP 23 & 22'!AE26 -> 20326406410 | N16: ='Consol SoFP 23 & 22'!BF26 -> 5180796035 | P16: Due from related parties
A17: Beban dibayar dimuka | J17: ='Consol SoFP 24'!AH31 -> 6267463919 | L17: ='Consol SoFP 23 & 22'!AE32 -> 11811728970 | N17: ='Consol SoFP 23 & 22'!BF32 -> 46432019959 | P17: Prepayments
A18: Pajak dibayar dimuka | J18: ='Consol SoFP 24'!AH32 -> 9836948341 | L18: ='Consol SoFP 23 & 22'!AE31 -> 2623976876 | N18: ='Consol SoFP 23 & 22'!BF31 -> 90969692 | P18: Prepaid taxes
A19: Restricted cash | J19: ='Consol SoFP 24'!AH34 -> 143195607918 | L19: ='Consol SoFP 23 & 22'!AE34 -> 159588593589 | N19: ='Consol SoFP 23 & 22'!BF34 -> 55354071673 | P19: Restricted cash
A20: Aset lancar lain-lain | J20: =SUM('Consol SoFP 24'!AH33,'Consol SoFP 24'!AH30,'Consol SoFP 24'!AH35) -> 2036699933 | L20: ='Consol SoFP 23 & 22'!AE35 -> 24013216750 | N20: ='Consol SoFP 23 & 22'!BF35 -> 12634397153 | P20: Other current assets
A22: Total Aset Lancar | J22: =SUM(J12:J20) -> 667054354077 | L22: =SUM(L12:L20) -> 670920678455 | N22: =SUM(N12:N20) -> 408171041394 | P22: Total current assets
A24: ASET TIDAK LANCAR | P24: NON-CURRENT ASSETS
A25: Piutang sewa - tidak lancar | J25: 0 | L25: ='Consol SoFP 23 & 22'!AE42 -> 2156177190 | N25: ='Consol SoFP 23 & 22'!BF42 -> 14398163289 | P25: Prepayments
A26: Aset tetap - bersih | J26: ='Consol SoFP 24'!AH43 -> 71907700936 | L26: ='Consol SoFP 23 & 22'!AE44 -> 21832710982 | N26: ='Consol SoFP 23 & 22'!BF44 -> 35664033274 | P26: Fixed assets - net
A27: Aset Hak Guna | J27: ='Consol SoFP 24'!AH45 -> 36242446809 | L27: ='Consol SoFP 23 & 22'!AE46 -> 11843914378 | N27: ='Consol SoFP 23 & 22'!BF46 -> 140145541230 | P27: Right of use assets
A28: Aset tak berwujud - bersih | J28: ='Consol SoFP 24'!AH44 -> 16469508674 | L28: ='Consol SoFP 23 & 22'!AE45 -> 24886088064 | N28: ='Consol SoFP 23 & 22'!BF45 -> 43488307487 | P28: Intangible assets - net
A29: Piutang Pemegang saham | J29: ='Consol SoFP 24'!AH46 -> 2314180101 | L29: ='Consol SoFP 23 & 22'!AE47 -> 2482200000 | N29: ='Consol SoFP 23 & 22'!BF47 -> 874125000 | P29: Shareholder Receivable
A30: Investasi | J30: 0 | L30: 0 | N30: 0 | P30: Investment
A31: Aset tidak lancar lainnya | J31: ='Consol SoFP 24'!AH49 -> 84860041916 | L31: ='Consol SoFP 23 & 22'!AE50 -> 12960995205 | N31: ='Consol SoFP 23 & 22'!BF50+'Consol SoFP 23 & 22'!BF48 -> 10947704500 | P31: Other non-current assets
A33: Total Aset Tidak Lancar | J33: =SUM(J25:J31) -> 211793878436 | L33: =SUM(L25:L31) -> 76162085819 | N33: =SUM(N25:N31) -> 245517874780 | P33: Total Non - Current Assets
A35: TOTAL ASET | J35: =+J22+J33 -> 878848232513 | L35: =+L22+L33 -> 747082764274 | N35: =+N22+N33 -> 653688916174 | P35: TOTAL ASSETS
A37: LIABILITAS DAN EKUITAS | P37: LIABILITES AND EQUITY
A39: LIABILITAS JANGKA PENDEK | P39: CURRENT LIABILITIES
A40: Utang usaha dan utang lain-lain | J40: =-SUM('Consol SoFP 24'!AH59:AH60,'Consol SoFP 24'!AH68:AH69) -> 100244378567 | L40: =-SUM('Consol SoFP 23 & 22'!AE60:AE61,'Consol SoFP 23 & 22'!AE70) -> 53941650149 | N40: =-'Consol SoFP 23 & 22'!BF60 -> 35633999745 | P40: Trade and other payables
A41: Utang sewa | J41: =-'Consol SoFP 24'!AH75 -> 44246726806 | L41: =-'Consol SoFP 23 & 22'!AE75 -> 57438550502 | N41: =-'Consol SoFP 23 & 22'!BF75 -> 52729712992 | P41: Lease Payables
A42: Utang bank jangka pendek | J42: =-SUM('Consol SoFP 24'!AH57) -> 109688388792 | L42: =-'Consol SoFP 23 & 22'!AE58 -> 141442017128 | N42: =-'Consol SoFP 23 & 22'!BF58 -> 43196374892 | P42: Short-term Bank Loan
A43: Utang Deposit | J43: =-'Consol SoFP 24'!AH64 -> 1597985933 | L43: =-'Consol SoFP 23 & 22'!AE65 -> 3998598175 | N43: =-'Consol SoFP 23 & 22'!BF65 -> 6108774604 | P43: Deposit payable
A44: Biaya yang masih harus dibayar | J44: =-SUM('Consol SoFP 24'!AH62:AH63) -> 28052747312 | L44: =-SUM('Consol SoFP 23 & 22'!AE63:AE64) -> 59423529841 | N44: =-SUM('Consol SoFP 23 & 22'!BF63:BF64) -> 83657606012 | P44: Accruals
A45: Utang Pembiayaan - jangka pendek | J45: =-'Consol SoFP 24'!AH71 -> 0 | L45: 0 | N45: 0 | P45: Consumer Financing Payables - Current Portion
A46: Pendapatan diterima dimuka | J46: =-'Consol SoFP 24'!AH74 -> 22024685439 | P46: Unearned Revenue
A47: Utang pihak berelasi | J47: =-'Consol SoFP 24'!AH66 -> 81841385213 | L47: =-'Consol SoFP 23 & 22'!AE67 -> 15917342497 | N47: =-'Consol SoFP 23 & 22'!BF67 -> 40302224 | P47: Due to related parties
A48: Utang pajak lainnya | J48: =-'Consol SoFP 24'!AH65 -> 351201384 | L48: =-'Consol SoFP 23 & 22'!AE66 -> 5484244074 | N48: =-'Consol SoFP 23 & 22'!BF66 -> 8775032472 | P48: Taxes payable - other taxes
A50: Total Liabilitas Jangka Pendek | J50: =SUM(J40:J48) -> 388047499446 | L50: =SUM(L40:L48) -> 337645932366 | N50: =SUM(N40:N48) -> 230141802941 | P50: Total Current Liabilities
...

Sheet SOPL
A1: PT DUMMY - C DAN ENTITAS ANAK
A2: LAPORAN LABA RUGI DAN PENGHASILAN KONSOLIDASI | Q2: PT DUMMY - C AND ITS SUBSIDIARIES
A3: KOMPREHENSIF LAIN | Q3: CONSOLIDATED STATEMENTS OF PROFIT OR LOSS
A4: UNTUK TAHUN-TAHUN YANG BERAKHIR | Q4: AND OTHER COMPREHENSIVE INCOME
A5: 31 DESEMBER 2024, 2023 DAN 2022 | Q5: FOR THE YEARS ENDED DECEMBER 31, 2024, 2023 AND 2022
A6: (Disajikan dalam Rupiah, kecuali dinyatakan lain) | Q6: (Expressed in Rupiah, unless otherwise stated)
G9: Catatan/ | K9: Audited | N9: As restated | Q9: As restated
G10: Notes | K10: 2024 | N10: 2023 | Q10: 2022
A13: Pendapatan | K13: =-'Consol SoPL-OCI 24'!AG16 -> 7.8864517e+11 | N13: =-'Consol SoPL-OCI 23 & 22'!AC16 -> 913482303388 | Q13: =-'Consol SoPL-OCI 23 & 22'!BD16 -> 3.749433e+11 | S13: Revenue
A14: Beban Pokok Pendapatan | G14: 16 | K14: =-'Consol SoPL-OCI 24'!AG17 -> -6.9736014e+11 | N14: =-'Consol SoPL-OCI 23 & 22'!AC17 -> -966810700161 | Q14: =-'Consol SoPL-OCI 23 & 22'!BD17 -> -3.2414255e+11 | S14: Cost of Revenue
A16: LABA BRUTO | K16: =SUM(K13:K14) -> 9.128503e+10 | N16: =SUM(N13:N14) -> -53328396773 | Q16: =SUM(Q13:Q14) -> 5.0800755e+10 | S16: GROSS PROFIT
A18: BEBAN USAHA | S18: OPERATING EXPENSES
A20: Umum dan administrasi | K20: =-'Consol SoPL-OCI 24'!AG24 -> -5.6012593e+11 | N20: =-'Consol SoPL-OCI 23 & 22'!AC24 -> -799753482326 | Q20: =-'Consol SoPL-OCI 23 & 22'!BD24 -> -5.673036e+11 | S20: General and administration
A21: Penjualan dan Pemasaran | K21: =-'Consol SoPL-OCI 24'!AG23 -> -7.2626305e+09 | N21: =-'Consol SoPL-OCI 23 & 22'!AC23 -> -32112230024 | Q21: =-'Consol SoPL-OCI 23 & 22'!BD23 -> -2.3395208e+10 | S21: Sales and Marketing
A22: Rugi penurunan nilai aset tetap, aset takberwujud dan aset hak guna | S22: Impairment Loss on fixed assets, intangible assets and
A23: dan aset hak guna | K23: =-'Consol SoPL-OCI 24'!AG27 -> 0 | N23: =-'Consol SoPL-OCI 23 & 22'!AC27 -> -32453747018 | Q23: =-'Consol SoPL-OCI 23 & 22'!BD27 -> 1.3268913e+09 | S23: Right of used assets
A24: Depresiasi dan Amortisasi | K24: =-'Consol SoPL-OCI 24'!AG25 -> -2.4155198e+10 | N24: =-'Consol SoPL-OCI 23 & 22'!AC25 -> -30622890261 | Q24: =-'Consol SoPL-OCI 23 & 22'!BD25 -> -9.2150701e+09 | S24: Depreciation and Amortization
A25: Kerugian penurunan nilai aset keuangan | K25: =-'Consol SoPL-OCI 24'!AG26 -> -11266205309 | N25: =-'Consol SoPL-OCI 23 & 22'!AC26 -> -1899458800 | Q25: =-'Consol SoPL-OCI 23 & 22'!BD26 -> -4.08681e+10 | S25: Professional fees
A26: Lain-lain, bersih | K26: =-'Consol SoPL-OCI 24'!AG28-'Consol SoPL-OCI 24'!AG38 -> -4.2550162e+09 | N26: =-'Consol SoPL-OCI 23 & 22'!AC28-'Consol SoPL-OCI 23 & 22'!AC38 -> -24815839951 | Q26: =-'Consol SoPL-OCI 23 & 22'!BD28-'Consol SoPL-OCI 23 & 22'!BD38 -> 29660476 | S26: Others - net
A28: Total Beban Usaha | K28: =SUM(K20:K26) -> -6.0706498e+11 | N28: =SUM(N20:N26) -> -921657648380 | Q28: =SUM(Q20:Q26) -> -6.3942542e+11 | S28: Total Operating Expense
A30: RUGI USAHA | K30: =K16+K28 -> -5.1577995e+11 | N30: =N16+N28 -> -974986045153 | Q30: =Q16+Q28 -> -5.8862467e+11 | S30: OPERATING LOSS
A32: PENGHASILAN (BEBAN) LAIN-LAIN | S32: OTHER INCOME (EXPENSES)
A33: Penghasilan Bunga | K33: =-'Consol SoPL-OCI 24'!AG35 -> 8.0255535e+09 | N33: =-'Consol SoPL-OCI 23 & 22'!AC35 -> 8.605882e+09 | Q33: =-'Consol SoPL-OCI 23 & 22'!BD35 -> 5.6403384e+09 | S33: Interest Income
A34: Beban Bunga | K34: =-'Consol SoPL-OCI 24'!AG36 -> -1.2803155e+10 | N34: =-'Consol SoPL-OCI 23 & 22'!AC36 -> -3.1914224e+10 | Q34: =-'Consol SoPL-OCI 23 & 22'!BD36 -> -1.4054873e+10 | S34: Interest Expense
A35: Untung Selisih Kurs Neto | K35: =-'Consol SoPL-OCI 24'!AG37 -> -939065125 | N35: =-'Consol SoPL-OCI 23 & 22'!AC37 -> 1566688058 | Q35: =-'Consol SoPL-OCI 23 & 22'!BD37 -> 51355510 | S35: Gain On foreign exchange, net
A37: Total beban lain-lain, neto | K37: =SUM(K31:K35) -> -5.7166663e+09 | N37: =SUM(N31:N35) -> -2.1741654e+10 | Q37: =SUM(Q31:Q35) -> -8.3631792e+09 | S37: Total other expenses, net
A39: RUGI SEBELUM BEBAN PAJAK
A40: PENGHASILAN | K40: =K30+K37 -> -5.2149661e+11 | N40: =N30+N37 -> -9.967277e+11 | Q40: =Q30+Q37 -> -5.9698785e+11 | S40: LOSS BEFORE INCOME TAX EXPENSE
A42: BEBAN PAJAK PENGHASILAN | K42: 0 | N42: =-'Consol SoPL-OCI 23 & 22'!AC56 -> -8372187235 | Q42: =-'Consol SoPL-OCI 23 & 22'!BD56 -> -3.4697822e+09 | S42: INCOME TAX EXPENSE
A44: RUGI TAHUN BERJALAN SEBELUM | S44: LOSS FOR THE YEAR BEFORE
A45: EFEK PENYESUAIAN PROFORMA | K45: =K40+K42 -> -5.2149661e+11 | N45: =N40+N42 -> -1.0050999e+12 | Q45: =Q40+Q42 -> -6.0045763e+11 | S45: EFFECT OF PROFORMA ADJUSTMENT
A47: EFEK DARI PENYESUAIAN PROFORMA | S47: EFFECT OF PROFORMA ADJUSTMENT
A48: ATAS LABA TAHUN BERJALAN | K48: =-'Consol SoPL-OCI 24'!AG61 -> 6.0462397e+09 | N48: =-'Consol SoPL-OCI 23 & 22'!AC61 -> 5.8403962e+10 | Q48: =-'Consol SoPL-OCI 23 & 22'!BD61 -> 3.3149995e+10 | S48: ON NET INCOME FOR THE YEAR
A50: RUGI TAHUN BERJALAN | K50: =K48+K45 -> -5.1545037e+11 | N50: =N48+N45 -> -9.4669592e+11 | Q50: =Q48+Q45 -> -5.6730763e+11 | S50: LOSS FOR THE YEAR
A52: PENGHASILAN KOMPERHENSIF LAIN | S52: OTHER COMPERHENSIVE INCOME
A53: Item yang tidak akan direklasifikasi ke laba rugi: | S53: Items that will not be reclassified to profit or loss:
A54: - Pengukuran kembali liabilitas imbalan | S54: - Remerasurementof employee benefits
B55: kerja, setelah pajak | K55: 0 | N55: =-SUM('Consol SoPL-OCI 23 & 22'!AC66:AC67) -> 6.1470357e+08 | Q55: =-SUM('Consol SoPL-OCI 23 & 22'!BD66:BD67) -> 6.3235994e+08 | T55: obligation, net of tax
A57: JUMLAH PENGHASILAN (RUGI) KOMPREHENSIF | S57: TOTAL COMPREHENSIVE INCOME (LOSS)
B58: TAHUN BERJALAN | K58: =K50+K55 -> -5.1545037e+11 | N58: =N50+N55 -> -9.4608122e+11 | Q58: =Q50+Q55 -> -5.6667527e+11 | T58: FOR THE YEAR

Sheet SOCE
A2: PT Dummy C and its Subsidiaries
A3: Statement of Change in Equity
A4: For period end December 31, 2024 | V4: n
D7: Notes | F7: Share Capital | H7: Advance Capital | J7: Additional Paid in Capital | L7: Capital proforma arising from restructuring transactions of entities under common control | N7: Other Comperhensive Income | P7: Share-Based Compensation Reserve | R7: Retained Earnings | T7: Subtotal | V7: Non-controlling interest | X7: Total Equity | Z7: Control
B10: Balance as of December 31, 2022 Audited | F10: 142427250000 | H10: =-'Consol SoFP 23 & 22'!AJ94 -> 3.5785358e+11 | N10: =-'Consol SoFP 23 & 22'!AJ105-'Consol SoFP 23 & 22'!AJ104 -> 8.9057972e+08 | P10: =-SUM('Consol SoFP 23 & 22'!AJ97:AJ98) -> 2.8533902e+10 | R10: =-'Consol SoFP 23 & 22'!AJ102-'Consol SoFP 23 & 22'!AJ101 -> -3.2367391e+11 | T10: =SUM(F10,H10,J10,L10,N10,P10,R10) -> 2.060314e+11 | X10: =SUM(T10:V10) -> 2.060314e+11
B12: Restatement PSAK 22 in Subsidiaries | L12: 0 | T12: =SUM(F12,H12,J12,L12,N12,P12,R12) -> 0 | X12: =SUM(T12:V12) -> 0 | Z12: 0
B14: Restatement effect due to Proforma adjustment | L14: =-'Proforma Adjustment'!R15 -> 3.5078825e+10 | T14: =SUM(F14,H14,J14,L14,N14,P14,R14) -> 3.5078825e+10 | V14: =-SUM('NCI Detail & Movement'!P48,'NCI Detail & Movement'!P49,'NCI Detail & Movement'!P51,'NCI Detail & Movement'!P56) -> 5.192101e+11 | X14: =SUM(T14:V14) -> 5.5428892e+11 | Z14: 0
B16: Effect on proforma adjustment
B17: on current income for the year | L17: =-'Proforma Adjustment'!S15 -> -3.3149995e+10 | T17: =SUM(F17,H17,J17,L17,N17,P17,R17) -> -3.3149995e+10 | V17: =-'NCI Detail & Movement'!P50 -> -3.8937387e+11 | X17: =SUM(T17:V17) -> -4.2252387e+11 | Z17: 0
B19: Effect on proforma adjustment
B20: on Current year ESOP Reserve | L20: =-'Proforma Adjustment'!U15 -> 1.075576e+08 | T20: =SUM(F20,H20,J20,L20,N20,P20,R20) -> 1.075576e+08 | V20: =-'NCI Detail & Movement'!P52 -> 3.1517635e+09 | X20: =SUM(T20:V20) -> 3.2593211e+09 | Z20: 0
B22: Effect on proforma adjustment
B23: on Current Year OCI emben | L23: =-'Proforma Adjustment'!T15 -> 57332944 | T23: =SUM(F23,H23,J23,L23,N23,P23,R23) -> 57332944 | V23: =-'NCI Detail & Movement'!P54 -> 1.680029e+09 | X23: =SUM(T23:V23) -> 1.7373619e+09 | Z23: 0
B25: Balance as of December 31, 2022 as Restated | F25: =SUM(F10,F12,F14,F17,F20,F23) -> 142427250000 | H25: =SUM(H10,H12,H14,H17,H20,H23) -> 3.5785358e+11 | J25: =SUM(J10,J12,J14,J17,J20,J23) -> 0 | L25: =SUM(L10,L12,L14,L17,L20,L23) -> 2.0937199e+09 | N25: =SUM(N10,N12,N14,N17,N20,N23) -> 8.9057972e+08 | P25: =SUM(P10,P12,P14,P17,P20,P23) -> 2.8533902e+10 | R25: =SUM(R10,R12,R14,R17,R20,R23) -> -3.2367391e+11 | T25: =SUM(T10,T12,T14,T17,T20,T23) -> 2.0812512e+11 | V25: =SUM(V10,V12,V14,V17,V20,V23) -> 1.3466801e+11 | X25: =SUM(X10,X12,X14,X17,X20,X23) -> 3.4279313e+11
B27: Per SoFP | F27: ='Consol SoFP 23 & 22'!BF93 -> -142427250000 | H27: ='Consol SoFP 23 & 22'!BF94 -> -357853579198 | J27: ='Consol SoFP 23 & 22'!BF95 -> 0 | L27: ='Consol SoFP 23 & 22'!BF106 -> -2093719896 | N27: =SUM('Consol SoFP 23 & 22'!BF104:BF105) -> -890579715 | P27: =SUM('Consol SoFP 23 & 22'!BF97:BF98) -> -28533901860 | R27: =SUM('Consol SoFP 23 & 22'!BF101:BF102) -> 323673912325 | T27: ='Consol SoFP 23 & 22'!BF109 -> -208125118344 | V27: ='Consol SoFP 23 & 22'!BF110 -> -134668014247 | X27: ='Consol SoFP 23 & 22'!BF112 -> -342793132591
B28: Difference | F28: =ROUND(F25+F27,0) -> 0 | H28: =ROUND(H25+H27,0) -> 0 | J28: =ROUND(J25+J27,0) -> 0 | L28: =ROUND(L25+L27,0) -> 0 | N28: =ROUND(N25+N27,0) -> 0 | P28: =ROUND(P25+P27,0) -> 0 | R28: =ROUND(R25+R27,0) -> 0 | T28: =ROUND(T25+T27,0) -> 1 | V28: =ROUND(V25+V27,0) -> 0 | X28: =ROUND(X25+X27,0) -> 1
H29: =-H28 -> 0
B30: Advance for Share Capital | F30: 0 | H30: 9.897029e+11 | R30: 0 | T30: =SUM(F30,H30,J30,L30,N30,P30,R30) -> 9.897029e+11 | X30: =SUM(T30:V30) -> 9.897029e+11
B32: Issuance of share Capital | F32: 344280825000 | H32: =-F32 -> -344280825000 | T32: =SUM(F32,H32,J32,L32,N32,P32,R32) -> 0 | X32: =SUM(T32:V32) -> 0
B34: Net income for the year | R34: =-'Consol SoPL-OCI 23 & 22'!AC86 -> -3.2620582e+11 | T34: =SUM(F34,H34,J34,L34,N34,P34,R34) -> -3.2620582e+11 | X34: =SUM(T34:V34) -> -3.2620582e+11
B36: Remeasurement Empolyee Benefit | N36: =-'Consol SoFP 23 & 22'!AE105 -> 614703573 | R36: =-'Consol SoPL-OCI 23 & 22'!AC88 -> 0 | T36: =SUM(F36,H36,J36,L36,N36,P36,R36) -> 614703573 | X36: =SUM(T36:V36) -> 614703573
B38: Additional Share-based Reserved | P38: =-'Consol SoFP 23 & 22'!AE98 -> 13850428637 | R38: =-'Consol SoPL-OCI 23 & 22'!AC90 -> 0 | T38: =SUM(F38,H38,J38,L38,N38,P38,R38) -> 13850428637 | X38: =SUM(T38:V38) -> 13850428637
B40: Proforma Capital from issuance additional share
B41: in subsidiaries | L41: =-'Proforma Adjustment'!E78+'Proforma Adjustment'!D97 -> 1.0455437e+09 | R41: 0 | T41: =SUM(F41,H41,J41,L41,N41,P41,R41) -> 1.0455437e+09 | V41: =-'NCI Detail & Movement'!F200 -> 5.0259513e+09 | X41: =SUM(T41:V41) -> 6.071495e+09
B43: Effect on proforma adjustment
B44: on net income for the year | L44: =-'Capital Proforma Control'!P61 -> -5.8403962e+10 | T44: =SUM(F44,H44,J44,L44,N44,P44,R44) -> -5.8403962e+10 | V44: =-'Consol SoPL-OCI 23 & 22'!AC87 -> -6.2049011e+11 | X44: =SUM(T44:V44) -> -6.7889407e+11
B46: Effect on proforma adjustment
B47: on Current year ESOP Reserve | L47: =-'Proforma Adjustment'!E86 -> 231177233 | T47: =SUM(F47,H47,J47,L47,N47,P47,R47) -> 231177233 | V47: =-'NCI Detail & Movement'!L200 -> 6.7741935e+09 | X47: =SUM(T47:V47) -> 7.0053707e+09
B49: Effect on proforma adjustment
B50: on Current Year OCI emben | L50: =-'Proforma Adjustment'!E90 -> 27756416 | T50: =SUM(F50,H50,J50,L50,N50,P50,R50) -> 27756416 | V50: =-('Consol SoPL-OCI 23 & 22'!AB94-'Consol SoPL-OCI 23 & 22'!AB87) -> 8.133471e+08 | X50: =SUM(T50:V50) -> 8.4110352e+08
B52: Balance as of December 31, 2023 as restated | F52: =SUM(F25,F30,F32,F34,F36,F38,F41,F44,F47,F50) -> 486708075000 | H52: =SUM(H25,H30,H32,H34,H36,H38,H41,H44,H47,H50) -> 1.0032756e+12 | J52: =SUM(J25,J30,J32,J34,J36,J38,J41,J44,J47,J50) -> 0 | L52: =SUM(L25,L30,L32,L34,L36,L38,L41,L44,L47,L50) -> -5.5005765e+10 | N52: =SUM(N25,N30,N32,N34,N36,N38,N41,N44,N47,N50) -> 1.5052833e+09 | P52: =SUM(P25,P30,P32,P34,P36,P38,P41,P44,P47,P50) -> 4.238433e+10 | R52: =SUM(R25,R30,R32,R34,R36,R38,R41,R44,R47,R50) -> -6.4987973e+11 | T52: =SUM(T25,T30,T32,T34,T36,T38,T41,T44,T47,T50) -> 8.2898785e+11 | V52: =SUM(V25,V30,V32,V34,V36,V38,V41,V44,V47,V50) -> -4.732086e+11 | X52: =SUM(X25,X30,X32,X34,X36,X38,X41,X44,X47,X50) -> 3.5577924e+11
B54: Per SoFP | F54: ='Consol SoFP 23 & 22'!AE93 -> -486708075000 | H54: ='Consol SoFP 23 & 22'!AE94 -> -1003275649843 | J54: =SUM('Consol SoFP 23 & 22'!AE95) -> 0 | L54: ='Consol SoFP 23 & 22'!AE106 -> 55005764507 | N54: =SUM('Consol SoFP 23 & 22'!AE104:AE105) -> -1505283288 | P54: =SUM('Consol SoFP 23 & 22'!AE97:AE98) -> -42384330497 | R54: =SUM('Consol SoFP 23 & 22'!AE101:AE102) -> 649879728743 | T54: ='Consol SoFP 23 & 22'!AE109 -> -828987845378 | V54: ='Consol SoFP 23 & 22'!AE110 -> 4.732086e+11 | X54: ='Consol SoFP 23 & 22'!AE112 -> -3.5577924e+11
B55: Difference | F55: =ROUND(F52+F54,0) -> 0 | H55: =ROUND(H52+H54,0) -> 0 | J55: =ROUND(J52+J54,0) -> 0 | L55: =ROUND(L52+L54,0) -> 1 | N55: =N52+N54 -> 0.375 | P55: =ROUND(P52+P54,0) -> 0 | R55: =ROUND(R52+R54,0) -> 1 | T55: =ROUND(T52+T54,0) -> 3 | V55: =ROUND(V52+V54,0) -> -2 | X55: =ROUND(X52+X54,0) -> 1
B57: Advance for Share Capital | F57: 0 | R57: 0 | T57: =SUM(F57,H57,J57,L57,N57,P57,R57) -> 0 | X57: =SUM(T57:V57) -> 0
B59: Issuance of share Capital | H59: 604970548439 | T59: =SUM(F59,H59,J59,L59,N59,P59,R59) -> 604970548439 | X59: =SUM(T59:V59) -> 604970548439
B61: Reclassification Non-controlling Interest
B62: into Retained earning from indirect ownership in Subsidiaries | R62: 0 | T62: =SUM(F62,H62,J62,L62,N62,P62,R62) -> 0 | V62: 0 | X62: =SUM(T62:V62) -> 0
B64: Net income for the year | R64: =-'Consol SoPL-OCI 24'!AG87 -> -2.5235239e+11 | T64: =SUM(F64,H64,J64,L64,N64,P64,R64) -> -2.5235239e+11 | V64: =-'Consol SoPL-OCI 24'!AG88 -> -2.6309798e+11 | X64: =SUM(T64:V64) -> -5.1545037e+11
B66: Remeasurement Empolyee Benefit | N66: 0 | R66: 0 | T66: =SUM(F66,H66,J66,L66,N66,P66,R66) -> 0 | V66: 0 | X66: =SUM(T66:V66) -> 0
B68: Additional Share-based Reserved | P68: 0 | R68: 0 | T68: =SUM(F68,H68,J68,L68,N68,P68,R68) -> 0 | V68: 0 | X68: =SUM(T68:V68) -> 0
...

Sheet CF 24
A1: PT Dummy - C and its subsidiaries | Z1: Restatement | AP1: Restatement | AY1: Restatement | AZ1: Restatement
A2: Consolidated Statement of Cash Flows
A3: December 31. 2024
E4: control | H4: =H97 -> 0 | I4: =I97 -> 0 | J4: =J97 -> 0 | K4: =K97 -> 0 | L4: =L97 -> 0 | M4: =M97 -> 0 | N4: =N97 -> 0 | O4: =O97 -> 0 | ... AF4: =AF97 -> 0 | AI4: =AI97 -> 0 | AJ4: =AJ97 -> 0 | AK4: =AK97 -> 0 | AL4: =AL97 -> 0 | AM4: =AM97 -> 0 | AN4: =AN97 -> 0 | AO4: =AO97 -> 0 | AP4: =AP97 -> 0 | AR4: =AR97 -> 0 | AS4: =AS97 -> 0 | AT4: =AT97 -> -0.27490234 | AU4: =AU97 -> 0 | AV4: =AV97 -> -1 | AW4: =AW97 -> -0.86421204 | AY4: =AY97 -> -3.8708801 | AZ4: =AZ97 -> 659.15817
F6: 0.42999268 | V6: Non-current asset
H7: Cash and cash equivalents | I7: Trade receivables, net | J7: Current portion of Lease receivables | K7: Loan Receivable Related Party, Net | L7: Other receivables net, | M7: Advance, prepaid expenses and other assets | N7: Restricted banks and time deposits (current and non-current) | O7: Prepaid tax | P7: Other Current Assets | Q7: Due from related parties, net (current and non-current) | R7: Lease receivables - non current | S7: Fixed assets, net | T7: Investment properties | U7: Right of use assets, net | V7: Intangible assets, net | W7: Shareholder Receivable | X7: Other non-current asset | Y7: Goodwill | Z7: Deferred tax assets, net | AA7: Deferred tax liabilities, net | AB7: Short-term bank loan | AC7: Trade payable | AD7: Other Payable | AE7: Deposit Payable | AF7: Loan Payable Related Party | AG7: Payable to Shareholder | AH7: Payable to Subsidiaries | AI7: Taxes payable | AJ7: Accrued expenses | AK7: Unearned Revenue | AL7: Borrowings | AM7: Liabilities related asset held for sale | AN7: Convertible bonds | AO7: Lease liabilities | AP7: Employee benefits liabilities | AQ7: Consumer Financing | AR7: Other Non current Liabilities | AS7: Share capital | AT7: Advance Capital | AU7: Share Based Compensation Reserve | AV7: Employee Benefit Liabilities | AW7: Capital proforma arising from restructuring transactions of entities under common control | AX7: SNTRESS | AY7: Retained earnings | AZ7: Non-controlling Interest | BA7: control
G8: 45657 | H8: ='Consol SoFP 24'!AH15 -> 61178535792 | I8: =SUM('Consol SoFP 24'!AH17:AH18,'Consol SoFP 24'!AH20) -> 244672056004 | J8: ='Consol SoFP 24'!AH22 -> 5217740512 | K8: =SUM('Consol SoFP 24'!AH25:AH26) -> 134787570854 | L8: =SUM('Consol SoFP 24'!AH28:AH29,'Consol SoFP 24'!AH23) -> 59861730804 | M8: =SUM('Consol SoFP 24'!AH32:AH33)+'Consol SoFP 24'!AH30 -> 10309535399 | N8: ='Consol SoFP 24'!AH34 -> 143195607918 | O8: ='Consol SoFP 24'!AH31 -> 6267463919 | P8: ='Consol SoFP 24'!AH35 -> 1564112875 | Q8: 0 | R8: ='Consol SoFP 24'!AH42 -> 0 | S8: ='Consol SoFP 24'!AH43 -> 71907700936 | U8: ='Consol SoFP 24'!AH45 -> 36242446809 | V8: ='Consol SoFP 24'!AH44 -> 16469508674 | W8: ='Consol SoFP 24'!AH46 -> 2314180101 | X8: ='Consol SoFP 24'!AH49 -> 84860041916 | AA8: ='Consol SoFP 24'!AH84 -> -11841969436 | AB8: ='Consol SoFP 24'!AH57 -> -109688388792 | AC8: =SUM('Consol SoFP 24'!AH59:AH60) -> -93585773120 | AD8: =SUM('Consol SoFP 24'!AH68:AH69) -> -6658605447 | AE8: ='Consol SoFP 24'!AH64 -> -1597985933 | AF8: ='Consol SoFP 24'!AH66 -> -81841385213 | AG8: ='Consol SoFP 24'!AH73 -> 0 | AH8: ='Consol SoFP 24'!AH72 -> 0 | AI8: ='Consol SoFP 24'!AH65 -> -351201384 | AJ8: =SUM('Consol SoFP 24'!AH62:AH63) -> -28052747312 | AK8: ='Consol SoFP 24'!AH74 -> -22024685439 | AL8: ='Consol SoFP 24'!AH71 -> 0 | AO8: ='Consol SoFP 24'!AH75+'Consol SoFP 24'!AH81 -> -98631811794 | AP8: ='Consol SoFP 24'!AH83 -> -4853302291 | AQ8: ='Consol SoFP 24'!AH82 -> 0 | AR8: ='Consol SoFP 24'!AH85 -> -4735334275 | AS8: ='Consol SoFP 24'!AH93 -> -486708075000 | AT8: ='Consol SoFP 24'!AH94 -> -1608246198282 | AU8: ='Consol SoFP 24'!AH98 -> -42384330497 | AV8: ='Consol SoFP 24'!AH104 -> -1505283289 | AX8: ='Consol SoFP 24'!AH96 -> 85320141313 | AY8: =SUM('Consol SoFP 24'!AH101:AH102) -> 902232119329 | AZ8: ='Consol SoFP 24'!AH110 -> 7.3630658e+11 | BA8: =SUM(H8:AZ8) -> -0.46325684
G9: 45291 | H9: ='Consol SoFP 23 & 22'!AE15 -> 75109486095 | I9: =SUM('Consol SoFP 23 & 22'!AE17:AE18,'Consol SoFP 23 & 22'!AE20) -> 323260364520 | J9: =SUM('Consol SoFP 23 & 22'!AE22) -> 15830303102 | K9: =SUM('Consol SoFP 23 & 22'!AE25:AE26) -> 20326406410 | L9: =SUM('Consol SoFP 23 & 22'!AE28:AE29) -> 38356602143 | M9: =SUM('Consol SoFP 23 & 22'!AE32) -> 11811728970 | N9: ='Consol SoFP 23 & 22'!AE34 -> 159588593589 | O9: ='Consol SoFP 23 & 22'!AE31 -> 2623976876 | P9: ='Consol SoFP 23 & 22'!AE35 -> 24013216750 | R9: ='Consol SoFP 23 & 22'!AE42 -> 2156177190 | S9: ='Consol SoFP 23 & 22'!AE44 -> 21832710982 | U9: ='Consol SoFP 23 & 22'!AE46 -> 11843914378 | V9: ='Consol SoFP 23 & 22'!AE45 -> 24886088064 | W9: ='Consol SoFP 23 & 22'!AE47 -> 2482200000 | X9: ='Consol SoFP 23 & 22'!AE50 -> 12960995205 | AA9: ='Consol SoFP 23 & 22'!AE84 -> -11841969435 | AB9: ='Consol SoFP 23 & 22'!AE58 -> -141442017128 | AC9: =SUM('Consol SoFP 23 & 22'!AE60:AE61) -> -48531295722 | AD9: ='Consol SoFP 23 & 22'!AE70 -> -5410354427 | AE9: ='Consol SoFP 23 & 22'!AE65 -> -3998598175 | AF9: ='Consol SoFP 23 & 22'!AE67 -> -15917342497 | AG9: ='Consol SoFP 23 & 22'!AE73 -> 0 | AH9: ='Consol SoFP 23 & 22'!AE72 -> 0 | AI9: ='Consol SoFP 23 & 22'!AE66 -> -5484244074 | AJ9: ='Consol SoFP 23 & 22'!AE63 -> -59423529841 | AK9: ='Consol SoFP 23 & 22'!AE74 -> 0 | AL9: ='Consol SoFP 23 & 22'!AE71 -> 0 | AO9: ='Consol SoFP 23 & 22'!AE81+'Consol SoFP 23 & 22'!AE75 -> -89665532815 | AP9: ='Consol SoFP 23 & 22'!AE82 -> -4853302291 | AQ9: ='Consol SoFP 23 & 22'!AE83 -> 0 | AR9: ='Consol SoFP 23 & 22'!AE85 -> -4735334275 | AS9: ='Consol SoFP 23 & 22'!AE93 -> -486708075000 | AT9: ='Consol SoFP 23 & 22'!AE94 -> -1003275649843 | AU9: =SUM('Consol SoFP 23 & 22'!AE97:AE98) -> -42384330497 | AV9: =SUM('Consol SoFP 23 & 22'!AE104:AE105) -> -1505283288 | AW9: ='Consol SoFP 23 & 22'!AE106 -> 55005764507 | AY9: =SUM('Consol SoFP 23 & 22'!AE101:AE102) -> 649879728743 | AZ9: ='Consol SoFP 23 & 22'!AE110 -> 4.732086e+11 | BA9: =SUM(H9:AZ9) -> -0.31237793
G10: Variance | H10: =H8-H9 -> -13930950303 | I10: =I8-I9 -> -78588308516 | J10: =J8-J9 -> -10612562590 | K10: =K8-K9 -> 114461164444 | L10: =L8-L9 -> 21505128661 | M10: =M8-M9 -> -1502193571 | N10: =N8-N9 -> -16392985671 | O10: =O8-O9 -> 3643487043 | ... AZ10: =AZ8-AZ9 -> 2.6309798e+11
A12: CASH FLOW FROM OPERATING ACTIVITIES
B13: Profit before income tax | F13: =ROUND(SUM(H13:AZ13),0) -> -521496612227 | AA13: 0 | AI13: 0 | AV13: 0 | AW13: =-'Supplementary CF 24'!M99 -> -6.0462397e+09 | AY13: =-'Consol SoPL-OCI 24'!AG87 -> -2.5235239e+11 | AZ13: =-'Consol SoPL-OCI 24'!AG88 -> -2.6309798e+11 | BA13: =F13-SUM(H13:AZ13) -> -0.0040893555 | BE13: Direct
BE14: Revenue
B15: Adjustment: | BE15: Add: Net change ar to cash
C16: Depreciation of fixed assets | F16: =ROUND(SUM(H16:AZ16),0) -> 18620446593 | S16: =-'Supplementary CF 24'!K24 -> 1.8620447e+10 | BA16: =F16-SUM(H16:AZ16) -> -0.27499771 | BE16: Add: Net movement of Unearned
C17: Provision for Impairment of Fixed Assets | F17: =ROUND(SUM(H17:AZ17),0) -> 0 | S17: =-'Supplementary CF 24'!O25 -> 0 | BA17: =F17-SUM(H17:AZ17) -> 0 | BE17: less: non-cash transaction related to AR
C18: Depreciation of right of use assets | F18: =ROUND(SUM(H18:AZ18),0) -> 9829951191 | U18: =-'Supplementary CF 24'!F43 -> 9829951191 | BA18: =F18-SUM(H18:AZ18) -> 0
C19: Provision for Impairment of Right of used assets | F19: =ROUND(SUM(H19:AZ19),0) -> 0 | U19: =-'Supplementary CF 24'!F44 -> 0 | BA19: =F19-SUM(H19:AZ19) -> 0
C20: Loss from early termination fo Lease | E20: l | F20: =ROUND(SUM(H20:AZ20),0) -> 0 | U20: =-'Supplementary CF 24'!F42 -> 0 | AO20: ='Supplementary CF 24'!F55 -> 0 | BA20: =F20-SUM(H20:AZ20) -> 0
C21: Amortization of intangible assets | F21: =ROUND(SUM(H21:AZ21),0) -> 8416579389 | V21: =-'Supplementary CF 24'!M66 -> 8.4165794e+09 | BA21: =F21-SUM(H21:AZ21) -> -0.0023345947
C22: Provision for Impairment of Intangible Assets | F22: =ROUND(SUM(H22:AZ22),0) -> 0 | V22: =-'Supplementary CF 24'!O67 -> 0 | BA22: =F22-SUM(H22:AZ22) -> 0
C23: Loss (Gain) on disposal of fixed assets | F23: =ROUND(SUM(H23:AZ23),0) -> 0 | S23: =-'Supplementary CF 24'!O23 -> 0 | BA23: =F23-SUM(H23:AZ23) -> 0
C24: Employee benefit expenses | F24: =ROUND(SUM(H24:AZ24),0) -> 0 | Z24: 0 | AP24: =-SUM('Supplementary CF 24'!O87:O88) -> 0 | AV24: 0 | BA24: =F24-SUM(H24:AZ24) -> 0
C25: Provision for impairment of trade receivables, net | F25: =ROUND(SUM(H25:AZ25),0) -> 0 | I25: =ROUND(SUM('Supplementary CF 24'!O10:O11),0) -> 0 | J25: 0 | Q25: 0 | BA25: =F25-SUM(H25:AZ25) -> 0
C26: Fair value of financial asset | F26: =ROUND(SUM(H26:AZ26),0) -> 0 | BA26: =F26-SUM(H26:AZ26) -> 0
C27: Share-based compensation reserve | F27: =ROUND(SUM(H27:AZ27),0) -> 0 | AU27: =-AU10 -> 0 | AV27: 0 | BA27: =F27-SUM(H27:AZ27) -> 0
C28: Interest income | F28: =ROUND(SUM(H28:AZ28),0) -> -8025553537 | Q28: 0 | AY28: ='Consol SoPL-OCI 24'!AG35 -> -8.0255535e+09 | BA28: =F28-SUM(H28:AZ28) -> 0.30000114
C29: Interest expense | F29: =ROUND(SUM(H29:AZ29),0) -> 12803154683 | AY29: ='Consol SoPL-OCI 24'!AG36 -> 1.2803155e+10 | BA29: =F29-SUM(H29:AZ29) -> 0.35000038
C30: Interest expense on lease | F30: =ROUND(SUM(H30:AZ30),0) -> 9784551649 | AO30: ='Supplementary CF 24'!M53 -> 9.7845516e+09 | BA30: =F30-SUM(H30:AZ30) -> 0.2365551
BA31: =F31-SUM(H31:AZ31) -> 0
F32: =SUM(F13:F31) -> -470067482259 | BA32: 0
B33: Changes in working capital: | BA33: =F33-SUM(H33:AZ33) -> 0
C34: Trade receivables, net | F34: =ROUND(SUM(H34:AZ34),0) -> 78588308516 | I34: =-I10-I25 -> 78588308516 | BA34: =F34-SUM(H34:AZ34) -> 0
C35: Other receivables, net | F35: =ROUND(SUM(H35:AZ35),0) -> -21337108766 | L35: =-L10-L59 -> -21505128661 | W35: =-W10 -> 168019899 | Z35: -4 | BA35: =F35-SUM(H35:AZ35) -> 0
C36: Other assets | F36: =ROUND(SUM(H36:AZ36),0) -> 23951297446 | M36: =-M10 -> 1502193571 | P36: =-P10 -> 22449103875 | BA36: =F36-SUM(H36:AZ36) -> 0
C37: Other non-current assets | F37: =ROUND(SUM(H37:AZ37),0) -> -71899046711 | X37: =-X10 -> -71899046711 | BA37: =F37-SUM(H37:AZ37) -> 0
C38: Trade and other payables | F38: =ROUND(SUM(H38:AZ38),0) -> 42709326002 | S38: =-'Supplementary CF 24'!O32 -> 0 | X38: 0 | AC38: =-AC10-AC57 -> 42709326002 | BA38: =F38-SUM(H38:AZ38) -> 0
C39: Deposit payable | F39: =ROUND(SUM(H39:AZ39),0) -> -2400612242 | AE39: =-AE10 -> -2400612242 | BA39: =F39-SUM(H39:AZ39) -> 0
C40: Unearned Revenue | F40: =ROUND(SUM(H40:AZ40),0) -> 22024685439 | AE40: =-AE11 -> 0 | AK40: =-AK10 -> 22024685439 | BA40: =F40-SUM(H40:AZ40) -> 0
C41: Accruals | F41: =ROUND(SUM(H41:AZ41),0) -> -31370782529 | AJ41: =-AJ10 -> -31370782529 | BA41: =F41-SUM(H41:AZ41) -> 0
C42: Taxes payable – other taxes | F42: =ROUND(SUM(H42:AZ42),0) -> -5133042690 | AI42: =-AI10-AI13 -> -5133042690 | BA42: =F42-SUM(H42:AZ42) -> 0
...

Sheet CF 23 as Restated
A1: PT Dummy - C and its Subsidiaries | Z1: Restatement | AM1: Restatement | AS1: Restatement | AT1: Restatement
A2: Consolidated Statement of Cash Flows
A3: December 31. 2023 - Restated CF
E4: control | J4: =J86 -> 0 | K4: =K86 -> 0 | L4: =L86 -> 0 | M4: =M86 -> 0 | N4: =N86 -> 0 | O4: =O86 -> 0 | P4: =P86 -> 0 | Q4: =Q86 -> 0 | ... BA4: =BA86 -> -2.2983217
H6: 0.42999268 | N6: Current Asset | V6: Non-current asset
J7: Cash and cash equivalents | K7: Trade receivables, net | L7: Current portion of Lease receivables | M7: Loan Receivable Related Party, Net | N7: Other receivables net, | O7: Advance, prepaid expenses and other assets | P7: Restricted banks and time deposits (current and non-current) | Q7: Prepaid tax | R7: Other Current Assets | S7: Due from related parties, net (current and non-current) | T7: Lease receivables - non current | U7: Fixed assets, net | V7: Investment properties | W7: Right of use assets, net | X7: Intangible assets, net | Y7: Shareholder Receivable | Z7: Other non-current asset | AA7: Goodwill | AB7: Deferred tax assets, net | AC7: Deferred tax liabilities, net | AD7: Short-term bank loan | AE7: Trade payable | AF7: Other Payable | AG7: Deposit Payable | AH7: Loan Payable Related Party | AI7: Payable to Shareholder | AJ7: Payable to Subsidiaries | AK7: Taxes payable | AL7: Accrued expenses | AM7: Unearned Revenue | AN7: Borrowings | AO7: Liabilities related asset held for sale | AP7: Convertible bonds | AQ7: Lease liabilities | AR7: Employee benefits liabilities | AS7: Consumer Financing | AT7: Other Non current Liabilities | AU7: Share capital | AV7: Advance Capital | AW7: Share Based Compensation Reserve | AX7: OCI - Employee benefit | AY7: Capital proforma arising from restructuring transactions of entities under common control | AZ7: Retained earnings | BA7: Non-controlling Interest | BB7: control
F8: 45291 | I8: 44926 | J8: ='CF 2024'!H9 -> 75109486095 | K8: ='CF 2024'!I9 -> 323260364520 | L8: ='CF 2024'!J9 -> 15830303102 | M8: ='CF 2024'!K9 -> 20326406410 | N8: ='CF 2024'!L9 -> 38356602143 | O8: ='CF 2024'!M9 -> 11811728970 | P8: ='CF 2024'!N9 -> 159588593589 | Q8: ='CF 2024'!O9 -> 2623976876 | ... AY8: ='CF 2024'!AW9 -> 55005764507 | AZ8: ='CF 2024'!AY9 -> 649879728743 | BA8: ='CF 2024'!AZ9 -> 4.732086e+11 | BB8: =SUM(J8:BA8) -> -0.31237793
F9: 44926 | I9: 44561 | J9: ='Consol SoFP 23 & 22'!BF15 -> 40661258337 | K9: =SUM('Consol SoFP 23 & 22'!BF17:BF18) -> 227940501708 | L9: ='Consol SoFP 23 & 22'!BF22 -> 14442442151 | M9: ='Consol SoFP 23 & 22'!BF26 -> 5180796035 | N9: ='Consol SoFP 23 & 22'!BF28 -> 5434584686 | O9: ='Consol SoFP 23 & 22'!BF32 -> 46432019959 | P9: ='Consol SoFP 23 & 22'!BF34 -> 55354071673 | Q9: ='Consol SoFP 23 & 22'!BF31 -> 90969692 | R9: ='Consol SoFP 23 & 22'!BF35 -> 12634397153 | T9: ='Consol SoFP 23 & 22'!BF42 -> 14398163289 | U9: ='Consol SoFP 23 & 22'!BF44 -> 35664033274 | W9: ='Consol SoFP 23 & 22'!BF46 -> 140145541230 | X9: ='Consol SoFP 23 & 22'!BF45 -> 43488307487 | Y9: ='Consol SoFP 23 & 22'!BF47 -> 874125000 | Z9: ='Consol SoFP 23 & 22'!BF50+'Consol SoFP 23 & 22'!BF48 -> 10947704500 | AC9: ='Consol SoFP 23 & 22'!BF84 -> -3469782201 | AD9: ='Consol SoFP 23 & 22'!BF58 -> -43196374892 | AE9: =SUM('Consol SoFP 23 & 22'!BF60:BF61) -> -35633999745 | AF9: =SUM('Consol SoFP 23 & 22'!BF69:BF70) -> 0 | AG9: ='Consol SoFP 23 & 22'!BF65 -> -6108774604 | AH9: ='Consol SoFP 23 & 22'!BF67 -> -40302224 | AK9: ='Consol SoFP 23 & 22'!BF66 -> -8775032472 | AL9: ='Consol SoFP 23 & 22'!BF63 -> -83657606012 | AQ9: ='Consol SoFP 23 & 22'!BF75+'Consol SoFP 23 & 22'!BF81 -> -125095664551 | AR9: ='Consol SoFP 23 & 22'!BF82 -> -4918246882 | AS9: 0 | AT9: ='Consol SoFP 23 & 22'!BF85 -> 0 | AU9: ='Consol SoFP 23 & 22'!BF93 -> -142427250000 | AV9: ='Consol SoFP 23 & 22'!BF94 -> -357853579198 | AW9: =SUM('Consol SoFP 23 & 22'!BF97:BF98) -> -28533901860 | AX9: =SUM('Consol SoFP 23 & 22'!BF104:BF105) -> -890579715 | AY9: ='Consol SoFP 23 & 22'!BF106 -> -2093719896 | AZ9: =SUM('Consol SoFP 23 & 22'!BF101:BF102) -> 323673912325 | BA9: ='Consol SoFP 23 & 22'!BF110 -> -134668014247 | BB9: =SUM(J9:BA9) -> 0
F10: Variance | I10: Variance | J10: =J8-J9 -> 34448227758 | K10: =K8-K9 -> 95319862812 | L10: =L8-L9 -> 1387860951 | M10: =M8-M9 -> 15145610375 | N10: =N8-N9 -> 32922017457 | O10: =O8-O9 -> -34620290989 | P10: =P8-P9 -> 104234521916 | Q10: =Q8-Q9 -> 2533007184 | ... BA10: =BA8-BA9 -> 6.0787662e+11
A12: CASH FLOW FROM OPERATING ACTIVITIES | F12: Before restatement | G12: Restatement | H12: After restatement
B13: Profit before income tax | F13: -3.0655578e+11 | G13: =H13-F13 -> -6.9017192e+11 | H13: =ROUND(SUM(J13:BA13),0) -> -996727698875 | AC13: ='Consol SoPL-OCI 23 & 22'!AC56 -> 8372187235 | AG13: 0 | AY13: ='Consol SoPL-OCI 23 & 22'!AC61 -> -5.8403962e+10 | AZ13: =-'Consol SoPL-OCI 23 & 22'!AC86 -> -3.2620582e+11 | BA13: =-'Consol SoPL-OCI 23 & 22'!AC87 -> -6.2049011e+11 | BB13: =H13-SUM(J13:BA13) -> 0.41638184
B15: Adjustment:
C16: Depreciation of fixed assets | F16: 1.2603248e+08 | G16: =H16-F16 -> 1.7543936e+10 | H16: =ROUND(SUM(J16:BA16),0) -> 17669968497 | U16: =-'Supplementary CF 23'!M24 -> 1.7669968e+10 | BB16: =H16-SUM(J16:BA16) -> 0.27225113
C17: Provision for Impairment of Fixed Assets | F17: 0 | G17: =H17-F17 -> 32453747018 | H17: =ROUND(SUM(J17:BA17),0) -> 32453747018 | U17: =-'Supplementary CF 23'!M25 -> 3.2453747e+10 | BB17: =H17-SUM(J17:BA17) -> 0.4851532
C18: Depreciation of right of use assets | F18: 0 | G18: =H18-F18 -> 83296105213 | H18: =ROUND(SUM(J18:BA18),0) -> 83296105213 | W18: =-'Supplementary CF 23'!F43 -> 8.3296105e+10 | BB18: =H18-SUM(J18:BA18) -> 0.40000916
C19: Provision for Impairment of Right of used assets | F19: 0 | G19: =H19-F19 -> 88325573940 | H19: =ROUND(SUM(J19:BA19),0) -> 88325573940 | W19: =-'Supplementary CF 23'!F44 -> 8.8325574e+10 | BB19: =H19-SUM(J19:BA19) -> -0.44999695
C20: Loss from early termination fo Lease | F20: 0 | G20: =H20-F20 -> -7662849305 | H20: =ROUND(SUM(J20:BA20),0) -> -7662849305 | W20: =-'Supplementary CF 23'!F42 -> 4.9691894e+10 | AQ20: ='Supplementary CF 23'!F55 -> -57354743376 | BB20: =H20-SUM(J20:BA20) -> -0.049995422
C21: Amortization of intangible assets | F21: 6.9373535e+09 | G21: =H21-F21 -> 3.9178496e+09 | H21: =ROUND(SUM(J21:BA21),0) -> 10855203098 | X21: =-'Supplementary CF 23'!M66 -> 1.0855203e+10 | BB21: =H21-SUM(J21:BA21) -> 0.27499962
C22: Provision for Impairment of Intangible Assets | F22: 7.7470163e+09 | G22: =H22-F22 -> -0.30000019 | H22: =ROUND(SUM(J22:BA22),0) -> 7747016325 | X22: =-'Supplementary CF 23'!M67 -> 7.7470163e+09 | BB22: =H22-SUM(J22:BA22) -> -0.30000019
C23: Loss (Gain) on disposal of fixed assets | F23: 0 | G23: =H23-F23 -> 133536375 | H23: =ROUND(SUM(J23:BA23),0) -> 133536375 | U23: =-'Supplementary CF 23'!M23 -> 133536375 | BB23: =H23-SUM(J23:BA23) -> 0
C24: Employee benefit expenses | F24: 5.019583e+08 | G24: =H24-F24 -> 8.889042e+08 | H24: =ROUND(SUM(J24:BA24),0) -> 1390862499 | AR24: =-AR10 -> -64944591 | AX24: =-'Supplementary CF 23'!E88 -> 6.1470357e+08 | AY24: =-'Supplementary CF 23'!K100 -> 27756416 | BA24: =-'NCI Detail & Movement'!J194 -> 8.133471e+08 | BB24: =H24-SUM(J24:BA24) -> -0.1500001
C25: Provision for impairment of trade receivables, net | F25: 2.5870488e+09 | G25: =H25-F25 -> -6.8759004e+08 | H25: =ROUND(SUM(J25:BA25),0) -> 1899458800 | K25: =SUM('Supplementary CF 23'!K10,'Supplementary CF 23'!K12) -> 1.8994588e+09 | L25: 0 | Q25: 0 | BB25: =H25-SUM(J25:BA25) -> -0.42500019
C26: Writing Off AR | F26: 0 | G26: =H26-F26 -> 5028226875 | H26: =ROUND(SUM(J26:BA26),0) -> 5028226875 | K26: =-'Supplementary CF 23'!K11 -> 5028226875 | L26: 0 | Q26: 0 | BB26: =H26-SUM(J26:BA26) -> 0
C27: Share-based compensation reserve | F27: 1.3850429e+10 | G27: =H27-F27 -> 7.0053707e+09 | H27: =ROUND(SUM(J27:BA27),0) -> 20855799337 | AR27: 0 | AT27: 0 | AW27: =-AW10 -> 13850428637 | AY27: =-'Supplementary CF 23'!K101 -> 2.3117723e+08 | BA27: =-'NCI Detail & Movement'!L194 -> 6.7741935e+09 | BB27: =H27-SUM(J27:BA27) -> -0.47499847
C28: Interest income | F28: -2.4693637e+10 | G28: =H28-F28 -> 1.6087755e+10 | H28: =SUM(J28:BA28) -> -8.605882e+09 | Q28: 0 | AZ28: ='Consol SoPL-OCI 23 & 22'!AC35 -> -8.605882e+09 | BB28: =H28-SUM(J28:BA28) -> 0
C29: Interest expense | F29: 3.8390263e+09 | G29: =H29-F29 -> 2.8075197e+10 | H29: =SUM(J29:BA29) -> 3.1914224e+10 | AZ29: ='Consol SoPL-OCI 23 & 22'!AC36 -> 3.1914224e+10 | BB29: =H29-SUM(J29:BA29) -> 0
C30: Interest expense on lease | F30: 0 | G30: =H30-F30 -> 13001777997 | H30: =ROUND(SUM(J30:BA30),0) -> 13001777997 | AQ30: ='Supplementary CF 23'!F53 -> 1.3001778e+10 | BB30: =H30-SUM(J30:BA30) -> 0.18213654
BB31: =H31-SUM(J31:BA31) -> 0
F32: =SUM(F13:F31) -> -2.9566055e+11 | G32: =SUM(G13:G31) -> -4.0276438e+11 | H32: =SUM(H13:H31) -> -6.9842493e+11 | BB32: 0
B33: Changes in working capital: | BB33: =H33-SUM(J33:BA33) -> 0
C34: Trade receivables, net | F34: =42097916433.825-3796710247.575 -> 3.8301206e+10 | G34: =H34-F34 -> -1.4054875e+11 | H34: =ROUND(SUM(J34:BA34),0) -> -102247548487 | K34: =-K10-K25-K26 -> -1.0224755e+11 | BB34: =H34-SUM(J34:BA34) -> 0.42500305
C35: Other receivables, net | F35: -1.8838057e+10 | G35: =H35-F35 -> -1.4083961e+10 | H35: =ROUND(SUM(J35:BA35),0) -> -32922017457 | N35: =-N10 -> -32922017457 | Z35: 0 | BB35: =H35-SUM(J35:BA35) -> 0
C36: Other assets | F36: -8.5554704e+08 | G36: =H36-F36 -> 3.5475838e+10 | H36: =ROUND(SUM(J36:BA36),0) -> 34620290989 | N36: 0 | O36: =-O10 -> 34620290989 | BB36: =H36-SUM(J36:BA36) -> 0
C37: Other non-current assets | F37: -2.0805585e+08 | G37: =H37-F37 -> -1.3184054e+10 | H37: =ROUND(SUM(J37:BA37),0) -> -13392110302 | R37: =-R10 -> -11378819597 | Z37: =-Z10 -> -2013290705 | BB37: =H37-SUM(J37:BA37) -> 0
C38: Trade and other payables | F38: 6.2904497e+09 | G38: =H38-F38 -> 5.839648e+09 | H38: =ROUND(SUM(J38:BA38),0) -> 12130097727 | AE38: =-AE10-AE56 -> 12130097727 | BB38: =H38-SUM(J38:BA38) -> 0
C39: Deposit payable | F39: -2.1101764e+09 | G39: =H39-F39 -> -0.1500001 | H39: =ROUND(SUM(J39:BA39),0) -> -2110176429 | AG39: =-AG10 -> -2110176429 | BB39: =H39-SUM(J39:BA39) -> 0
C40: Accruals | F40: 0 | G40: =H40-F40 -> -24234076171 | H40: =ROUND(SUM(J40:BA40),0) -> -24234076171 | AL40: =-AL10 -> -24234076171 | BB40: =H40-SUM(J40:BA40) -> 0
C41: Taxes payable – other taxes | F41: -1.8831866e+10 | G41: =H41-F41 -> 1.3008071e+10 | H41: =ROUND(SUM(J41:BA41),0) -> -5823795582 | Q41: =-Q10 -> -2533007184 | AK41: =-AK10 -> -3290788398 | BB41: =H41-SUM(J41:BA41) -> 0
C42: Other non-current liabilities | F42: -1.7758503e+09 | G42: =H42-F42 -> 6.5111845e+09 | H42: =ROUND(SUM(J42:BA42),0) -> 4735334275 | AN42: =-AN10 -> 0 | AT42: =-AT10 -> 4735334275 | BB42: =H42-SUM(J42:BA42) -> 0
BB43: =H43-SUM(J43:BA43) -> 0
...

Sheet WP Consol

Sheet Control
A2: Retained Earnings
D4: 0.51 | E4: 0.51 | F4: 0.51 | G4: 0.51 | H4: 0.51 | J4: 0.51
D5: =100%-D4 -> 0.49 | E5: =100%-E4 -> 0.49 | F5: =100%-F4 -> 0.49 | G5: =100%-G4 -> 0.49 | H5: =100%-H4 -> 0.49 | J5: =100%-J4 -> 0.49
C7: PT Dummy C | D7: PT Dummy A - Consol | E7: PT Dummy - D | F7: PT Dummy - E | G7: PT Dummy - F | H7: PT Dummy - G | J7: Elimination | L7: Elimination
A11: Beginning Balance RE - Jan 1 2022 | C11: ='Consol SoFP 23 & 22'!AJ101 -> 145740154214 | D11: ='Consol SoFP 23 & 22'!AT101 -> -20240927228 | E11: ='Consol SoFP 23 & 22'!AM101 -> 1.2996164e+11 | F11: ='Consol SoFP 23 & 22'!AP101 -> 0 | G11: ='Consol SoFP 23 & 22'!AQ101 -> -1.1332579e+10 | H11: ='Consol SoFP 23 & 22'!AY101 -> 0 | J11: =SUM('Consol SoFP 23 & 22'!BD101:BE101) -> -9.8388134e+10 | L11: =SUM(C11:H11,J11) -> 145740154214
A12: Current Profit | C12: ='Consol SoPL-OCI 23 & 22'!AH86 -> 1.7793376e+11 | D12: ='Consol SoPL-OCI 23 & 22'!AT86 -> 3.9420352e+10 | E12: ='Consol SoPL-OCI 23 & 22'!AK86 -> 3.8207448e+11 | F12: ='Consol SoPL-OCI 23 & 22'!AN86 -> 2.8261882e+08 | G12: ='Consol SoPL-OCI 23 & 22'!AQ86 -> 574553968 | H12: 0 | J12: =SUM('Consol SoFP 23 & 22'!BD102:BE102) -> -4.2235201e+11 | L12: =SUM(C12:H12,J12) -> 1.7793376e+11
A13: As of December 31, 2022 | C13: =SUM(C11:C12) -> 3.2367391e+11 | D13: =SUM(D11:D12) -> 1.9179424e+10 | E13: =SUM(E11:E12) -> 5.1203612e+11 | F13: =SUM(F11:F12) -> 2.8261882e+08 | G13: =SUM(G11:G12) -> -1.0758025e+10 | H13: =SUM(H11:H12) -> 0 | J13: =SUM(H13:I13) -> 0 | L13: =SUM(L11:L12) -> 3.2367391e+11
A14: Per BS | C14: =SUM('Consol SoFP 23 & 22'!AJ101:AJ102) -> 3.2367391e+11 | D14: =SUM('Consol SoFP 23 & 22'!AT101:AT102) -> 1.9179424e+10 | E14: =SUM('Consol SoFP 23 & 22'!AM101:AM102) -> 5.1203612e+11 | F14: =SUM('Consol SoFP 23 & 22'!AP101:AP102) -> 2.8261882e+08 | G14: =SUM('Consol SoFP 23 & 22'!AQ101:AQ102) -> -1.0758025e+10 | H14: ='Consol SoFP 23 & 22'!AY101 -> 0 | J14: =SUM(H14:I14) -> 0 | L14: =SUM('Consol SoFP 23 & 22'!BF101:BF102) -> 323673912325
A15: Diff | C15: =C13-C14 -> 0 | D15: =D13-D14 -> 0 | E15: =E13-E14 -> 0 | F15: =F13-F14 -> 0 | G15: =G13-G14 -> 0 | H15: =H13-H14 -> 0 | J15: =SUM(H15:I15) -> 0 | L15: =SUM(J15:K15) -> 0
A17: Beginning Balance RE - Jan 1 2023 | C17: =C13 -> 3.2367391e+11 | D17: =D13 -> 1.9179424e+10 | E17: =E13 -> 5.1203612e+11 | F17: =F13 -> 2.8261882e+08 | G17: =G13 -> -1.0758025e+10 | H17: =H13 -> 0 | J17: =SUM('Consol SoFP 23 & 22'!AC101:AD101) -> -5.2074014e+11 | L17: =SUM(C17:H17,J17) -> 3.2367391e+11
A18: Current Profit | C18: ='Consol SoPL-OCI 23 & 22'!G86 -> 3.0717049e+11 | D18: ='Consol SoPL-OCI 23 & 22'!S86 -> 7.9178339e+10 | E18: ='Consol SoPL-OCI 23 & 22'!J86 -> 6.0319819e+11 | F18: ='Consol SoPL-OCI 23 & 22'!M86 -> -2677772539 | G18: ='Consol SoPL-OCI 23 & 22'!P86 -> -1013465132 | H18: 0 | J18: =SUM('Consol SoFP 23 & 22'!AC102:AD102) -> -6.5964996e+11 | L18: =SUM(C18:H18,J18) -> 3.2620582e+11
A19: As of December 31, 2023 | C19: =SUM(C17:C18) -> 6.308444e+11 | D19: =SUM(D17:D18) -> 9.8357763e+10 | E19: =SUM(E17:E18) -> 1.1152343e+12 | F19: =SUM(F17:F18) -> -2.3951537e+09 | G19: =SUM(G17:G18) -> -1.1771491e+10 | H19: =SUM(H17:H18) -> 0 | J19: =SUM(J17:J18) -> -1.1803901e+12 | L19: =SUM(L17:L18) -> 6.4987973e+11
A20: Per BS | C20: =SUM('Consol SoFP 23 & 22'!H101:H102) -> 6.308444e+11 | D20: =SUM('Consol SoFP 23 & 22'!T101:T102) -> 9.8357763e+10 | E20: =SUM('Consol SoFP 23 & 22'!K101:K102) -> 1.1152343e+12 | F20: =SUM('Consol SoFP 23 & 22'!N101:N102) -> -2.3951537e+09 | G20: =SUM('Consol SoFP 23 & 22'!Q101:Q102) -> -1.1771491e+10 | H20: ='Consol SoFP 23 & 22'!AY107 -> 0 | L20: =SUM('Consol SoFP 23 & 22'!AE101:AE102) -> 649879728743
A21: Diff | C21: =C19-C20 -> 0 | D21: =D19-D20 -> -0.62319946 | E21: =E19-E20 -> 1.7248535 | F21: =F19-F20 -> 0 | G21: =G19-G20 -> 0.25 | H21: =H19-H20 -> 0 | L21: =L19-L20 -> 0.94311523
A23: Beginning Balance RE - Jan 1 2024 | C23: =C19 -> 6.308444e+11 | D23: =D19 -> 9.8357763e+10 | E23: =E19 -> 1.1152343e+12 | F23: =F19 -> -2.3951537e+09 | G23: =G19 -> -1.1771491e+10 | H23: =H19 -> 0 | J23: =SUM('Consol SoFP 23 & 22'!AC107:AD107) -> 0 | L23: =SUM(C23:H23,J23) -> 1.8302698e+12
A24: Current Profit | C24: ='Consol SoPL-OCI 24'!E63+'Consol SoPL-OCI 24'!F63 -> 232074381913 | D24: ='Consol SoPL-OCI 24'!W87 -> 9.1244059e+09 | E24: ='Consol SoPL-OCI 24'!M87 -> 2.4367652e+11 | F24: ='Consol SoPL-OCI 24'!P79 -> 10891649906 | G24: ='Consol SoPL-OCI 24'!T79 -> 36098801827 | H24: ='Consol SoFP 24'!Y102 -> -8.971568e+08
A25: Equity adjustment - Current Profit | C25: =SUM('Consol SoFP 24'!F102:G102) -> 1.9370965e+10 | D25: ='Consol SoPL-OCI 23 & 22'!S92 -> 0 | E25: ='Consol SoPL-OCI 23 & 22'!J92 -> 0 | F25: ='Consol SoPL-OCI 23 & 22'!M92 -> 0 | G25: ='Consol SoPL-OCI 23 & 22'!P92 -> 0 | H25: 0 | J25: =SUM('Consol SoFP 23 & 22'!AC108:AD108) -> 0 | L25: =SUM(C25:H25,J25) -> 1.9370965e+10
A26: As of December 31, 2024 | C26: =SUM(C23:C25) -> 8.8228974e+11 | D26: =SUM(D23:D25) -> 1.0748217e+11 | E26: =SUM(E23:E25) -> 1.3589108e+12 | F26: =SUM(F23:F25) -> 8.4964962e+09 | G26: =SUM(G23:G25) -> 2.4327311e+10 | H26: =SUM(H23:H25) -> -8.971568e+08 | J26: =SUM(J23:J25) -> 0 | L26: =SUM(L23:L25) -> 1.8496408e+12
A27: Per BS - Before re Reconciliation | C27: =SUM('Consol SoFP 24'!H101:H102) -> 8.8228974e+11 | D27: =SUM('Consol SoFP 24'!V101:V102) -> 1.0748217e+11 | E27: =SUM('Consol SoFP 24'!L101:L102) -> 1.3589108e+12 | F27: =SUM('Consol SoFP 24'!M101:M102) -> 8207054749 | G27: =SUM('Consol SoFP 24'!S101:S102) -> 2.4327311e+10 | H27: 0 | L27: =SUM('Consol SoFP 23 & 22'!AE107:AE108) -> 0
A28: Diff | C28: =C26-C27 -> 3.2749023 | D28: =D26-D27 -> -0.29432678 | E28: =E26-E27 -> 11.015625 | F28: =F26-F27 -> 2.8944144e+08 | G28: =G26-G27 -> -0.59949493 | H28: 0 | L28: =L26-L27 -> 1.8496408e+12
A30: RE Reconciliation:
A31: 1) PT Dummy - D
A32: Accrued Expense | F32: =-F28 -> -2.8944144e+08
A34: Beginning Balance RE - Jan 1 2024 | C34: =C23 -> 6.308444e+11 | D34: =D23 -> 9.8357763e+10 | E34: =E23 -> 1.1152343e+12 | F34: =F23 -> -2.3951537e+09 | G34: =G23 -> -1.1771491e+10 | H34: =H23 -> 0 | J34: =J23 -> 0 | L34: =L23 -> 1.8302698e+12
A35: Current Profit | C35: =C24 -> 232074381913 | D35: =D24 -> 9.1244059e+09 | E35: ='Consol SoPL-OCI 24'!M98 -> 2.4367652e+11 | F35: ='Consol SoPL-OCI 24'!P90 -> 10891649906 | G35: ='Consol SoPL-OCI 24'!T90 -> 36098801827 | H35: ='Consol SoFP 24'!Y102 -> -8.971568e+08
A36: Equity adjustment - Current Profit | C36: =C25 -> 1.9370965e+10 | D36: ='Consol SoPL-OCI 23 & 22'!S103 -> 0 | E36: ='Consol SoPL-OCI 23 & 22'!J103 -> 0 | F36: ='Consol SoPL-OCI 23 & 22'!M103 -> 0 | G36: ='Consol SoPL-OCI 23 & 22'!P103 -> 0 | H36: 0 | J36: =SUM('Consol SoFP 23 & 22'!AC119:AD119) -> 0 | L36: =SUM(C36:H36,J36) -> 1.9370965e+10
A37: As of December 31, 2024 | C37: =SUM(C34:C36) -> 8.8228974e+11 | D37: =SUM(D34:D36) -> 1.0748217e+11 | E37: =SUM(E34:E36) -> 1.3589108e+12 | F37: =SUM(F34:F36) -> 8.4964962e+09 | G37: =SUM(G34:G36) -> 2.4327311e+10 | H37: =SUM(H34:H36) -> -8.971568e+08 | J37: =SUM(J34:J36) -> 0 | L37: =SUM(L34:L36) -> 1.8496408e+12
A38: Per BS - Before After Reconciliation | C38: =SUM('Consol SoFP 24'!H101:H102) -> 8.8228974e+11 | D38: =SUM('Consol SoFP 24'!V101:V102) -> 1.0748217e+11 | E38: =SUM('Consol SoFP 24'!L101:L102) -> 1.3589108e+12 | F38: =SUM('Consol SoFP 24'!O101:O102) -> 8.4964962e+09 | G38: =SUM('Consol SoFP 24'!S101:S102) -> 2.4327311e+10 | H38: 0 | L38: =SUM('Consol SoFP 23 & 22'!AE118:AE119) -> 6.5241163e+11
A39: Diff | C39: =C37-C38 -> 3.2749023 | D39: =D37-D38 -> -0.29432678 | E39: =E37-E38 -> 11.015625 | F39: =F37-F38 -> 0 | G39: =G37-G38 -> -0.59949493 | H39: 0 | L39: =L37-L38 -> 1.1972292e+12
A41: Investment
C44: Investment | D44: Proforma | E44: Proforma Adjustment | F44: Proforma Adjustment | G44: Equity | H44: Total | J44: Elimination | L44: Elimination
C45: Per Book | D45: Adjustment PY | E45: Current Profit CY | F45: Investment value should be | G45: Adjustment | H45: Before Elimination | J45: PT Dummy C Consol | L45: PT Dummy C Consol
A48: PT Dummy A - Consol | C48: 240975000 | D48: =SUM('Proforma Adjustment'!N123:O123) -> -4.9921484e+10 | E48: ='Proforma Adjustment'!E136 -> 7.7806288e+09 | F48: ='Proforma Adjustment'!D139 -> 4.2140855e+10 | G48: =-'Consol SoPL-OCI 24'!G48 -> -1.2434076e+10 | H48: =SUM(C48:G48) -> -1.2193101e+10 | J48: =SUM('Elimination 2024'!H57,'Elimination 2024'!G62,'Elimination 2024'!H67) -> 1.2193101e+10 | L48: =SUM(H48,J48) -> 0.15010643
A49: PT Dummy - D | C49: =SUM('BS RP Disclosure 2024'!E253:F253) -> 21504957075 | D49: =SUM('Proforma Adjustment'!N120:O120) -> -1.4831474e+10 | E49: ='Proforma Adjustment'!E112 -> -2.910673e+09 | F49: ='Proforma Adjustment'!D115 -> 1.7742147e+10 | G49: =-'Consol SoPL-OCI 24'!G45 -> -5.1306523e+09 | H49: =SUM(C49:G49) -> 1.6374305e+10 | J49: =SUM('Elimination 2024'!H7,'Elimination 2024'!G10,'Elimination 2024'!H18,'Elimination 2024'!H23,'Elimination 2024'!G27) -> 6.2119903e+10 | L49: =SUM(H49,J49) -> 7.8494208e+10 | M49: =L49/2 -> 3.9247104e+10
A50: PT Dummy - E | C50: ='BS RP Disclosure 2024'!F254 -> 12049420 | D50: =SUM('Proforma Adjustment'!N121:O121) -> 1.2335771e+09 | E50: ='Proforma Adjustment'!E120 -> -1.5828349e+09 | F50: ='Proforma Adjustment'!D123 -> 3.4925771e+08 | G50: =-'Consol SoPL-OCI 24'!G46 -> -3.9719066e+09 | H50: =SUM(C50:G50) -> -3.9598572e+09 | J50: =SUM('Elimination 2024'!H31,'Elimination 2024'!G36,'Elimination 2024'!H41) -> 3.9598578e+09 | L50: =SUM(H50,J50) -> 670
A51: PT Dummy - F | C51: ='BS RP Disclosure 2024'!F255 -> 2510156250 | D51: =SUM('Proforma Adjustment'!N122:O122) -> 8.5136164e+09 | E51: ='Proforma Adjustment'!D127 -> -9.3333607e+09 | F51: ='Proforma Adjustment'!E132 -> 8.1974424e+08 | G51: =-'Consol SoPL-OCI 24'!G47 -> -9.0770283e+09 | H51: =SUM(C51:G51) -> -6.566872e+09 | J51: =SUM('Elimination 2024'!H44,'Elimination 2024'!G49,'Elimination 2024'!G53) -> 6.566872e+09 | L51: =SUM(H51,J51) -> -0.14200592
A52: PT Dummy - G
C53: =SUM(C48:C51) -> 24268137745 | D53: =SUM(D48:D51) -> -5.5005765e+10 | E53: =SUM(E48:E51) -> -6.0462397e+09 | F53: =SUM(F48:F51) -> 6.1052005e+10 | G53: =SUM(G48:G51) -> -3.0613663e+10 | H53: =SUM(H48:H51) -> -6.3455247e+09 | J53: =SUM(J48:J51) -> 8.4839734e+10 | L53: =SUM(L48:L51) -> 7.8494209e+10
C54: =SUM('BS RP Disclosure 2024'!E261:F261) -> 24268137745 | D54: =SUM('Consol SoFP 24'!Z40:AA40) -> -5.5005765e+10 | E54: =-'Consol SoPL-OCI 24'!AA50 -> -6.0462397e+09 | G54: =SUM('Consol SoFP 24'!F40) -> -30613662987 | H54: ='Consol SoFP 24'!AE40 -> -6.3258372e+09 | J54: ='Consol SoFP 24'!AG40 -> -1.1007427e+11 | L54: ='Consol SoFP 24'!AH40 -> 0
C55: =C53-C54 -> 0 | D55: =D53-D54 -> 0 | E55: =E53-E54 -> 0 | G55: =G53-G54 -> 0.084030151 | H55: =H53-H54 -> -19687500 | J55: =J53-J54 -> 1.94914e+11 | L55: =L53-L54 -> 7.8494209e+10
...

Sheet Consol SoFP 24
C3: PT Dummy - C and its Subsidiaries
C4: Matter:
C5: Statement of Financial Position
L7: oke
H8: Dummy - C | L8: Dummy - D | O8: Dummy - E | S8: Dummy F | V8: Dummy - A | Y8: Dummy G
B9: Control to A=LE+E | D9: =D114+D53 -> 0 | E9: =E114+E53 -> 0 | H9: =H114+H53 -> 0 | I9: =I114+I53 -> 0 | J9: =J114+J53 -> 0 | L9: =L114+L53 -> 0 | M9: =M114+M53 -> 0 | O9: =O114+O53 -> 0 | P9: =P114+P53 -> 0 | Q9: =Q114+Q53 -> 0 | S9: =S114+S53 -> 0 | T9: =T114+T53 -> 0 | V9: =V114+V53 -> 0 | W9: =W114+W53 -> 0 | Y9: =Y114+Y53 -> 0 | Z9: =Z114+Z53 -> 0 | AA9: =AA114+AA53 -> 0 | AB9: =AB114+AB53 -> 0 | AC9: =SUM(AC12:AC114) -> 0 | AD9: =SUM(AD12:AD114) -> 0 | AE9: =AE114+AE53 -> 0 | AF9: =SUM(AF12:AF114) -> 3.6625151e+12 | AG9: =SUM(AG12:AG114) -> -3.6625151e+12 | AH9: =AH114+AH53 -> -0.18823242
B10: Description | D10: Per Book | E10: CLA | F10: Adjustment Equity Method | G10: Adjustment at consol | H10: Dummy - C | I10: Per Book | J10: CLA | K10: Adjustment at consol | L10: Dummy - D | M10: Dummy - E | N10: Adjustment at consol | O10: Dummy - E | P10: Per Book | Q10: CLA | R10: Adjustment at consol | S10: Dummy F | T10: Dummy - A | U10: Adjustment at consol | V10: Dummy - A | W10: Dummy G | X10: Adjustment at consol | Y10: Dummy G | Z10: Proforma Adjustment | AC10: Adjustment/ Reclassification | AE10: Combined | AF10: Elimination Entries | AH10: Consolidated
D11: 45657 | E11: 45657 | H11: 45657 | I11: 45657 | J11: 45657 | L11: 45657 | M11: 45657 | O11: 45657 | P11: 45657 | Q11: 45657 | S11: 45657 | T11: 45657 | V11: 45657 | W11: 45657 | Y11: 45657 | Z11: 44926 | AA11: 45291 | AB11: 45657 | AC11: Dr. | AD11: Cr. | AE11: 45657 | AF11: Dr. | AG11: Cr. | AH11: 45657
B13: ASSET
B14: CURRENT ASSET
B15: Cash and cash equivalents | D15: 62677974049 | E15: =-41826334020-24038265825+7250000000 -> -58614599845 | H15: =SUM(D15:E15) -> 4063374204 | I15: 37552005067 | J15: -11610679986 | L15: =SUM(I15:K15) -> 25941325081 | M15: 887896090 | O15: =SUM(M15:N15) -> 887896090 | P15: 3588753174 | Q15: 44193733 | S15: =SUM(P15:R15) -> 3632946907 | T15: 25054867533 | V15: =SUM(T15:U15) -> 25054867533 | W15: 1598125977 | Y15: =SUM(W15:X15) -> 1598125977 | AE15: =SUM(H15,L15,Z15,AA15,AC15:AD15,O15,S15,V15,Y15,AB15) -> 61178535792 | AH15: =ROUND(SUM(AE15:AG15),0) -> 61178535792
B16: Trade receivables | W16: 0
B17: Trade Receivables - Third Parties | D17: -7632229507 | E17: 7632229507 | H17: =SUM(D17:G17) -> 0 | I17: 13726195227 | J17: =26831819127-0.25 -> 2.6831819e+10 | L17: =SUM(I17:K17) -> 4.0558014e+10 | M17: 1464025584 | O17: =SUM(M17:N17) -> 1464025584 | P17: 3.7459812e+10 | Q17: -3.7459812e+10 | S17: =SUM(P17:R17) -> 0 | T17: =161473988972--0.67529296875 -> 1.6147399e+11 | V17: =SUM(T17:U17) -> 1.6147399e+11 | W17: 23251725 | Y17: =SUM(W17:X17) -> 23251725 | AE17: =SUM(H17,L17,Z17,AA17,AC17:AD17,O17,S17,V17,Y17,AB17) -> 2.0351928e+11 | AH17: =ROUND(SUM(AE17:AG17),0) -> 203519280635
B18: Trade Receivables - Related Parties | D18: -3721021958 | E18: 21936578161 | G18: ='Adjustment Consol'!J10+'Adjustment Consol'!J7+'Adjustment Consol'!I33+'Adjustment Consol'!I36+'Adjustment Consol'!I39+'Adjustment Consol'!J22+'Adjustment Consol'!I24 -> -4.5996643e+09 | H18: =SUM(D18:G18) -> 1.3615892e+10 | I18: 3698150207 | J18: 10840235364 | K18: ='Adjustment Consol'!I55 -> 2.204243e+09 | L18: =SUM(I18:K18) -> 1.6742629e+10 | M18: 0 | O18: =SUM(M18:N18) -> 0 | P18: 469001723 | Q18: 31647238381 | S18: =SUM(P18:R18) -> 32116240104 | T18: 18820641340 | V18: =SUM(T18:U18) -> 18820641340 | W18: 0 | Y18: =SUM(W18:X18) -> 0 | AE18: =SUM(H18,L18,Z18,AA18,AC18:AD18,O18,S18,V18,Y18,AB18) -> 8.1295402e+10 | AG18: =SUM('Elimination 2024'!H150,'Elimination 2024'!H153,'Elimination 2024'!H156,'Elimination 2024'!H159,'Elimination 2024'!H162,'Elimination 2024'!H165) -> -4.6323999e+10 | AH18: =ROUND(SUM(AE18:AG18),0) -> 34971402798
B19: Unbilled Receivable | W19: 0
B20: Unbilled - Third Parties | D20: 0 | E20: 0 | H20: =SUM(D20:G20) -> 0 | I20: 0 | J20: 0 | L20: =SUM(I20:K20) -> 0 | M20: 0 | O20: =SUM(M20:N20) -> 0 | P20: 13938025090 | Q20: -8.3884414e+09 | S20: =SUM(P20:R20) -> 5.5495836e+09 | T20: 0 | V20: =SUM(T20:U20) -> 0 | W20: 6.3178893e+08 | Y20: =SUM(W20:X20) -> 6.3178893e+08 | AE20: =SUM(H20,L20,Z20,AA20,AC20:AD20,O20,S20,V20,Y20,AB20) -> 6.1813726e+09 | AH20: =ROUND(SUM(AE20:AG20),0) -> 6181372571
B21: Unbilled - Related Parties | D21: 0 | E21: 0 | H21: =SUM(D21:G21) -> 0 | I21: 0 | J21: 0 | L21: =SUM(I21:K21) -> 0 | M21: 0 | O21: =SUM(M21:N21) -> 0 | P21: 0 | Q21: 0 | S21: =SUM(P21:R21) -> 0 | T21: 0 | V21: =SUM(T21:U21) -> 0 | W21: 0 | Y21: =SUM(W21:X21) -> 0 | AE21: =SUM(H21,L21,Z21,AA21,AC21:AD21,O21,S21,V21,Y21,AB21) -> 0 | AH21: =ROUND(SUM(AE21:AG21),0) -> 0
B22: Current portion of Lease receivables | D22: 0 | E22: 0 | H22: =SUM(D22:G22) -> 0 | I22: 17986480292 | J22: -12768739780 | L22: =SUM(I22:K22) -> 5217740512 | M22: 0 | O22: =SUM(M22:N22) -> 0 | P22: 0 | Q22: 0 | S22: =SUM(P22:R22) -> 0 | T22: 0 | V22: =SUM(T22:U22) -> 0 | W22: 0 | Y22: =SUM(W22:X22) -> 0 | AE22: =SUM(H22,L22,Z22,AA22,AC22:AD22,O22,S22,V22,Y22,AB22) -> 5217740512 | AH22: =ROUND(SUM(AE22:AG22),0) -> 5217740512
B23: Employee Receivables | D23: 236250000 | E23: 0 | H23: =SUM(D23:G23) -> 236250000 | I23: 507315342 | J23: 0 | L23: =SUM(I23:K23) -> 507315342 | M23: 0 | O23: =SUM(M23:N23) -> 0 | P23: 0 | Q23: 0 | S23: =SUM(P23:R23) -> 0 | T23: 0 | V23: =SUM(T23:U23) -> 0 | W23: 0 | Y23: =SUM(W23:X23) -> 0 | AE23: =SUM(H23,L23,Z23,AA23,AC23:AD23,O23,S23,V23,Y23,AB23) -> 743565342 | AH23: =ROUND(SUM(AE23:AG23),0) -> 743565342
B24: Loan Receivable | W24: 0
B25: Loan Receivable - Third Parties | D25: 2684635361 | E25: 0 | G25: ='Adjustment Consol'!I42 -> 4.2483385e+08 | H25: =SUM(D25:G25) -> 3.1094692e+09 | I25: 0 | J25: 0 | L25: =SUM(I25:K25) -> 0 | M25: 0 | O25: =SUM(M25:N25) -> 0 | P25: 0 | Q25: 0 | S25: =SUM(P25:R25) -> 0 | T25: 0 | V25: =SUM(T25:U25) -> 0 | W25: 0 | Y25: =SUM(W25:X25) -> 0 | AC25: 0 | AE25: =SUM(H25,L25,Z25,AA25,AC25:AD25,O25,S25,V25,Y25,AB25) -> 3.1094692e+09 | AH25: =ROUND(SUM(AE25:AG25),0) -> 3109469207
